Workbook

Sheet Matrix
A1: Smell | B1: File | C1: Code unit | D1: PMD | E1: ChatGPT R1 | F1: ChatGPT R2 | G1: ChatGPT R3 | H1: DeepSeek R1 | I1: DeepSeek R2 | J1: DeepSeek R3 | K1: ChatGPT runs (of 3) | L1: DeepSeek runs (of 3) | M1: Notes
A2: Long Method | B2: cli/CommandLine.java | C2: CommandLine.getParsedOptionValues(Option,Supplier<T[]>) | D2: 0 | E2: 0 | F2: 0 | G2: 0 | H2: 0 | I2: 1 | J2: 1 | K2: =SUM(E2:G2) -> 0 | L2: =SUM(H2:J2) -> 2
A3: Long Method | B3: cli/DefaultParser.java | C3: DefaultParser.handleShortAndLongOption(String) | D3: 1 | E3: 1 | F3: 1 | G3: 1 | H3: 1 | I3: 1 | J3: 1 | K3: =SUM(E3:G3) -> 3 | L3: =SUM(H3:J3) -> 3
A4: Long Method | B4: cli/DefaultParser.java | C4: DefaultParser.handleToken(String) | D4: 0 | E4: 0 | F4: 0 | G4: 0 | H4: 0 | I4: 1 | J4: 1 | K4: =SUM(E4:G4) -> 0 | L4: =SUM(H4:J4) -> 2
A5: Long Method | B5: cli/DefaultParser.java | C5: DefaultParser.parse(Options,Properties,NonOptionAction,String[]) | D5: 0 | E5: 0 | F5: 0 | G5: 0 | H5: 1 | I5: 1 | J5: 1 | K5: =SUM(E5:G5) -> 0 | L5: =SUM(H5:J5) -> 3
A6: Long Method | B6: cli/GnuParser.java | C6: GnuParser.flatten(Options,String[],boolean) | D6: 1 | E6: 1 | F6: 0 | G6: 1 | H6: 1 | I6: 0 | J6: 1 | K6: =SUM(E6:G6) -> 2 | L6: =SUM(H6:J6) -> 2
A7: Long Method | B7: cli/HelpFormatter.java | C7: HelpFormatter.appendOptions(Appendable,int,Options,int,int) | D7: 1 | E7: 1 | F7: 1 | G7: 1 | H7: 1 | I7: 1 | J7: 1 | K7: =SUM(E7:G7) -> 3 | L7: =SUM(H7:J7) -> 3
A8: Long Method | B8: cli/HelpFormatter.java | C8: HelpFormatter.appendWrappedText(Appendable,int,int,String) | D8: 0 | E8: 0 | F8: 0 | G8: 1 | H8: 0 | I8: 0 | J8: 0 | K8: =SUM(E8:G8) -> 1 | L8: =SUM(H8:J8) -> 0
A9: Long Method | B9: cli/HelpFormatter.java | C9: HelpFormatter.findWrapPos(String,int,int) | D9: 0 | E9: 0 | F9: 0 | G9: 0 | H9: 1 | I9: 0 | J9: 0 | K9: =SUM(E9:G9) -> 0 | L9: =SUM(H9:J9) -> 1
A10: Long Method | B10: cli/HelpFormatter.java | C10: HelpFormatter.printHelp(PrintWriter,int,String,String,Options,int,int,String,boolean) | D10: 0 | E10: 0 | F10: 0 | G10: 0 | H10: 1 | I10: 1 | J10: 0 | K10: =SUM(E10:G10) -> 0 | L10: =SUM(H10:J10) -> 2
A11: Long Method | B11: cli/HelpFormatter.java | C11: HelpFormatter.printUsage(PrintWriter,int,String,Options) | D11: 0 | E11: 1 | F11: 1 | G11: 0 | H11: 1 | I11: 0 | J11: 0 | K11: =SUM(E11:G11) -> 2 | L11: =SUM(H11:J11) -> 1
A12: Long Method | B12: cli/Parser.java | C12: Parser.parse(Options,String[],Properties,boolean) | D12: 1 | E12: 0 | F12: 0 | G12: 1 | H12: 1 | I12: 0 | J12: 0 | K12: =SUM(E12:G12) -> 1 | L12: =SUM(H12:J12) -> 1
A13: Long Method | B13: cli/Parser.java | C13: Parser.processProperties(Properties) | D13: 0 | E13: 0 | F13: 0 | G13: 1 | H13: 0 | I13: 0 | J13: 0 | K13: =SUM(E13:G13) -> 1 | L13: =SUM(H13:J13) -> 0
... A16: Long Method | B16: cli/TypeHandler.java | C16: TypeHandler.putDefaultMap(Map) | D16: 0 | E16: 0 | F16: 0 | G16: 0 | H16: 0 | I16: 1 | J16: 0 | K16: =SUM(E16:G16) -> 0 | L16: =SUM(H16:J16) -> 1
A17: Long Method | B17: cli/help/HelpFormatter.java | C17: HelpFormatter.getTableDefinition(Iterable<Option>) | D17: 0 | E17: 0 | F17: 0 | G17: 1 | H17: 0 | I17: 0 | J17: 0 | K17: =SUM(E17:G17) -> 1 | L17: =SUM(H17:J17) -> 0 | M17: Different class from cli/HelpFormatter.java (same name, help sub-package).
A18: Long Method | B18: cli/help/TextHelpAppendable.java | C18: TextHelpAppendable.adjustTableFormat(TableDefinition) | D18: 1 | E18: 0 | F18: 0 | G18: 1 | H18: 1 | I18: 1 | J18: 0 | K18: =SUM(E18:G18) -> 1 | L18: =SUM(H18:J18) -> 2 | M18: ChatGPT run 3 evidence is generic (no specific code elements quoted).
A19: Long Method | B19: cli/help/TextStyle.java | C19: TextStyle.pad(boolean,CharSequence) | D19: 1 | E19: 1 | F19: 0 | G19: 1 | H19: 0 | I19: 0 | J19: 0 | K19: =SUM(E19:G19) -> 2 | L19: =SUM(H19:J19) -> 0
A20: God Class | B20: cli/CommandLine.java | C20: CommandLine | D20: 1 | E20: 0 | F20: 0 | G20: 0 | H20: 1 | I20: 1 | J20: 1 | K20: =SUM(E20:G20) -> 0 | L20: =SUM(H20:J20) -> 3
A21: God Class | B21: cli/DefaultParser.java | C21: DefaultParser | D21: 1 | E21: 0 | F21: 0 | G21: 0 | H21: 1 | I21: 1 | J21: 1 | K21: =SUM(E21:G21) -> 0 | L21: =SUM(H21:J21) -> 3
A22: God Class | B22: cli/HelpFormatter.java | C22: HelpFormatter | D22: 1 | E22: 1 | F22: 1 | G22: 1 | H22: 1 | I22: 1 | J22: 1 | K22: =SUM(E22:G22) -> 3 | L22: =SUM(H22:J22) -> 3
A23: God Class | B23: cli/Option.java | C23: Option | D23: 1 | E23: 0 | F23: 0 | G23: 0 | H23: 1 | I23: 1 | J23: 1 | K23: =SUM(E23:G23) -> 0 | L23: =SUM(H23:J23) -> 3
A24: God Class | B24: cli/Options.java | C24: Options | D24: 0 | E24: 0 | F24: 0 | G24: 0 | H24: 0 | I24: 0 | J24: 1 | K24: =SUM(E24:G24) -> 0 | L24: =SUM(H24:J24) -> 1
A25: God Class | B25: cli/Parser.java | C25: Parser | D25: 1 | E25: 0 | F25: 0 | G25: 0 | H25: 0 | I25: 0 | J25: 0 | K25: =SUM(E25:G25) -> 0 | L25: =SUM(H25:J25) -> 0
A26: God Class | B26: cli/PatternOptionBuilder.java | C26: PatternOptionBuilder | D26: 0 | E26: 0 | F26: 0 | G26: 0 | H26: 0 | I26: 0 | J26: 1 | K26: =SUM(E26:G26) -> 0 | L26: =SUM(H26:J26) -> 1
A27: God Class | B27: cli/TypeHandler.java | C27: TypeHandler | D27: 0 | E27: 0 | F27: 0 | G27: 0 | H27: 0 | I27: 0 | J27: 1 | K27: =SUM(E27:G27) -> 0 | L27: =SUM(H27:J27) -> 1
A28: God Class | B28: cli/help/TextHelpAppendable.java | C28: TextHelpAppendable | D28: 0 | E28: 0 | F28: 0 | G28: 0 | H28: 1 | I28: 1 | J28: 1 | K28: =SUM(E28:G28) -> 0 | L28: =SUM(H28:J28) -> 3
A29: Long Parameter List | B29: cli/DefaultParser.java | C29: DefaultParser.parse(Options,Properties,NonOptionAction,String[]) | D29: 0 | E29: 0 | F29: 0 | G29: 1 | H29: 1 | I29: 1 | J29: 1 | K29: =SUM(E29:G29) -> 1 | L29: =SUM(H29:J29) -> 3
A30: Long Parameter List | B30: cli/HelpFormatter.java | C30: HelpFormatter.appendOptions(Appendable,int,Options,int,int) | D30: 1 | E30: 0 | F30: 0 | G30: 1 | H30: 1 | I30: 0 | J30: 0 | K30: =SUM(E30:G30) -> 1 | L30: =SUM(H30:J30) -> 1 | M30: Parameter type written "A" by some runs / PMD (generic <A extends Appendable>); treated as Appendable.
A31: Long Parameter List | B31: cli/HelpFormatter.java | C31: HelpFormatter.printHelp(PrintWriter,int,String,String,Options,int,int,String) | D31: 1 | E31: 1 | F31: 0 | G31: 0 | H31: 1 | I31: 1 | J31: 1 | K31: =SUM(E31:G31) -> 1 | L31: =SUM(H31:J31) -> 3
A32: Long Parameter List | B32: cli/HelpFormatter.java | C32: HelpFormatter.printHelp(PrintWriter,int,String,String,Options,int,int,String,boolean) | D32: 1 | E32: 1 | F32: 1 | G32: 1 | H32: 1 | I32: 1 | J32: 1 | K32: =SUM(E32:G32) -> 3 | L32: =SUM(H32:J32) -> 3
A33: Long Parameter List | B33: cli/HelpFormatter.java | C33: HelpFormatter.printHelp(String,String,Options,String,boolean) | D33: 1 | E33: 0 | F33: 0 | G33: 0 | H33: 0 | I33: 1 | J33: 0 | K33: =SUM(E33:G33) -> 0 | L33: =SUM(H33:J33) -> 1
A34: Long Parameter List | B34: cli/HelpFormatter.java | C34: HelpFormatter.printHelp(int,String,String,Options,String) | D34: 1 | E34: 0 | F34: 0 | G34: 0 | H34: 1 | I34: 0 | J34: 0 | K34: =SUM(E34:G34) -> 0 | L34: =SUM(H34:J34) -> 1
A35: Long Parameter List | B35: cli/HelpFormatter.java | C35: HelpFormatter.printHelp(int,String,String,Options,String,boolean) | D35: 1 | E35: 1 | F35: 0 | G35: 0 | H35: 1 | I35: 1 | J35: 1 | K35: =SUM(E35:G35) -> 1 | L35: =SUM(H35:J35) -> 3
A36: Long Parameter List | B36: cli/HelpFormatter.java | C36: HelpFormatter.printOptions(PrintWriter,int,Options,int,int) | D36: 1 | E36: 0 | F36: 0 | G36: 1 | H36: 0 | I36: 0 | J36: 0 | K36: =SUM(E36:G36) -> 1 | L36: =SUM(H36:J36) -> 0
A37: Long Parameter List | B37: cli/HelpFormatter.java | C37: HelpFormatter.renderOptions(StringBuffer,int,Options,int,int) | D37: 1 | E37: 0 | F37: 0 | G37: 1 | H37: 0 | I37: 0 | J37: 0 | K37: =SUM(E37:G37) -> 1 | L37: =SUM(H37:J37) -> 0
A38: Long Parameter List | B38: cli/Option.java | C38: Option(String,String,boolean,String) | D38: 0 | E38: 0 | F38: 0 | G38: 1 | H38: 1 | I38: 1 | J38: 0 | K38: =SUM(E38:G38) -> 1 | L38: =SUM(H38:J38) -> 2 | M38: Constructor. DS run 1 printed a garbled "Code unit" line for it (kept as one detection). LLMs call it borderline (4 params).
A39: Long Parameter List | B39: cli/Options.java | C39: Options.addOption(String,String,boolean,String) | D39: 0 | E39: 0 | F39: 0 | G39: 0 | H39: 1 | I39: 0 | J39: 0 | K39: =SUM(E39:G39) -> 0 | L39: =SUM(H39:J39) -> 1
A40: Long Parameter List | B40: cli/Options.java | C40: Options.addOption(String,boolean,String) | D40: 0 | E40: 0 | F40: 0 | G40: 0 | H40: 1 | I40: 0 | J40: 0 | K40: =SUM(E40:G40) -> 0 | L40: =SUM(H40:J40) -> 1
A41: Long Parameter List | B41: cli/Options.java | C41: Options.addRequiredOption(String,String,boolean,String) | D41: 0 | E41: 0 | F41: 0 | G41: 0 | H41: 1 | I41: 0 | J41: 0 | K41: =SUM(E41:G41) -> 0 | L41: =SUM(H41:J41) -> 1
A42: Long Parameter List | B42: cli/help/AbstractHelpFormatter.java | C42: AbstractHelpFormatter.printHelp(String,String,Iterable<Option>,String,boolean) | D42: 1 | E42: 0 | F42: 0 | G42: 0 | H42: 0 | I42: 0 | J42: 0 | K42: =SUM(E42:G42) -> 0 | L42: =SUM(H42:J42) -> 0
...

Sheet Table1
A1: Comparison Pair | B1: Smell Type | C1: Static Detections | D1: LLM Detections (Run 1) | E1: Common | F1: Static Only | G1: LLM Only | H1: Overlap (%) | I1: Comments
A2: PMD vs ChatGPT (Run 1) | B2: Long Method | C2: =SUMIFS(Matrix!$D$2:$D$46,Matrix!$A$2:$A$46,B2) -> 7 | D2: =SUMIFS(Matrix!$E$2:$E$46,Matrix!$A$2:$A$46,B2) -> 7 | E2: =COUNTIFS(Matrix!$A$2:$A$46,B2,Matrix!$D$2:$D$46,1,Matrix!$E$2:$E$46,1) -> 5 | F2: =C2-E2 -> 2 | G2: =D2-E2 -> 2 | H2: =IF(C2+D2-E2=0,0,E2/(C2+D2-E2)) -> 0.55555556 | I2: Missed Parser.parse and TextHelpAppendable.adjustTableFormat; added printUsage (NCSS 18) and parsePattern (NCSS 28), both under PMD's threshold of 30.
A3: PMD vs ChatGPT (Run 1) | B3: God Class | C3: =SUMIFS(Matrix!$D$2:$D$46,Matrix!$A$2:$A$46,B3) -> 5 | D3: =SUMIFS(Matrix!$E$2:$E$46,Matrix!$A$2:$A$46,B3) -> 1 | E3: =COUNTIFS(Matrix!$A$2:$A$46,B3,Matrix!$D$2:$D$46,1,Matrix!$E$2:$E$46,1) -> 1 | F3: =C3-E3 -> 4 | G3: =D3-E3 -> 0 | H3: =IF(C3+D3-E3=0,0,E3/(C3+D3-E3)) -> 0.2 | I3: Flagged only HelpFormatter. PMD-only: CommandLine, DefaultParser, Option, Parser.
A4: PMD vs ChatGPT (Run 1) | B4: Long Parameter List | C4: =SUMIFS(Matrix!$D$2:$D$46,Matrix!$A$2:$A$46,B4) -> 10 | D4: =SUMIFS(Matrix!$E$2:$E$46,Matrix!$A$2:$A$46,B4) -> 3 | E4: =COUNTIFS(Matrix!$A$2:$A$46,B4,Matrix!$D$2:$D$46,1,Matrix!$E$2:$E$46,1) -> 3 | F4: =C4-E4 -> 7 | G4: =D4-E4 -> 0 | H4: =IF(C4+D4-E4=0,0,E4/(C4+D4-E4)) -> 0.3 | I4: Flagged only the 6-, 8- and 9-parameter printHelp overloads. PMD also flags seven 5-parameter methods, none reported.
A5: PMD vs DeepSeek (Run 1) | B5: Long Method | C5: =SUMIFS(Matrix!$D$2:$D$46,Matrix!$A$2:$A$46,B5) -> 7 | D5: =SUMIFS(Matrix!$H$2:$H$46,Matrix!$A$2:$A$46,B5) -> 11 | E5: =COUNTIFS(Matrix!$A$2:$A$46,B5,Matrix!$D$2:$D$46,1,Matrix!$H$2:$H$46,1) -> 6 | F5: =C5-E5 -> 1 | G5: =D5-E5 -> 5 | H5: =IF(C5+D5-E5=0,0,E5/(C5+D5-E5)) -> 0.5 | I5: Missed only TextStyle.pad; added 5 methods below PMD's threshold (printHelp 9-param NCSS 12, printUsage 18, findWrapPos 17, DefaultParser.parse 16, parsePattern 28).
A6: PMD vs DeepSeek (Run 1) | B6: God Class | C6: =SUMIFS(Matrix!$D$2:$D$46,Matrix!$A$2:$A$46,B6) -> 5 | D6: =SUMIFS(Matrix!$H$2:$H$46,Matrix!$A$2:$A$46,B6) -> 5 | E6: =COUNTIFS(Matrix!$A$2:$A$46,B6,Matrix!$D$2:$D$46,1,Matrix!$H$2:$H$46,1) -> 4 | F6: =C6-E6 -> 1 | G6: =D6-E6 -> 1 | H6: =IF(C6+D6-E6=0,0,E6/(C6+D6-E6)) -> 0.66666667 | I6: Matched 4 of 5; missed Parser; added TextHelpAppendable, which PMD did not flag.
A7: PMD vs DeepSeek (Run 1) | B7: Long Parameter List | C7: =SUMIFS(Matrix!$D$2:$D$46,Matrix!$A$2:$A$46,B7) -> 10 | D7: =SUMIFS(Matrix!$H$2:$H$46,Matrix!$A$2:$A$46,B7) -> 10 | E7: =COUNTIFS(Matrix!$A$2:$A$46,B7,Matrix!$D$2:$D$46,1,Matrix!$H$2:$H$46,1) -> 5 | F7: =C7-E7 -> 5 | G7: =D7-E7 -> 5 | H7: =IF(C7+D7-E7=0,0,E7/(C7+D7-E7)) -> 0.33333333 | I7: Matched 5 of 10 (all printHelp overloads and appendOptions). Added 3- and 4-parameter methods (Options.addOption, Option ctor, DefaultParser.parse); missed printOptions, renderOptions and both AbstractHelpFormatter methods.

Sheet Table2
A1: LLM | B1: Smell Type | C1: 1 Run Only | D1: Exactly 2 Runs | E1: All 3 Runs | F1: Total Distinct | G1: Consistency (%) | H1: Mean Explanation Quality (/3)
A2: ChatGPT | B2: Long Method | C2: =COUNTIFS(Matrix!$A$2:$A$46,B2,Matrix!$K$2:$K$46,1) -> 5 | D2: =COUNTIFS(Matrix!$A$2:$A$46,B2,Matrix!$K$2:$K$46,2) -> 5 | E2: =COUNTIFS(Matrix!$A$2:$A$46,B2,Matrix!$K$2:$K$46,3) -> 2 | F2: =SUM(C2:E2) -> 12 | G2: =IF(F2=0,0,E2/F2) -> 0.16666667 | H2: =IFERROR(AVERAGEIFS(Explanations!$H$2:$H$12,Explanations!$A$2:$A$12,A2,Explanations!$B$2:$B$12,B2),"n/a") -> 3
A3: ChatGPT | B3: God Class | C3: =COUNTIFS(Matrix!$A$2:$A$46,B3,Matrix!$K$2:$K$46,1) -> 0 | D3: =COUNTIFS(Matrix!$A$2:$A$46,B3,Matrix!$K$2:$K$46,2) -> 0 | E3: =COUNTIFS(Matrix!$A$2:$A$46,B3,Matrix!$K$2:$K$46,3) -> 1 | F3: =SUM(C3:E3) -> 1 | G3: =IF(F3=0,0,E3/F3) -> 1 | H3: =IFERROR(AVERAGEIFS(Explanations!$H$2:$H$12,Explanations!$A$2:$A$12,A3,Explanations!$B$2:$B$12,B3),"n/a") -> 3
A4: ChatGPT | B4: Long Parameter List | C4: =COUNTIFS(Matrix!$A$2:$A$46,B4,Matrix!$K$2:$K$46,1) -> 7 | D4: =COUNTIFS(Matrix!$A$2:$A$46,B4,Matrix!$K$2:$K$46,2) -> 0 | E4: =COUNTIFS(Matrix!$A$2:$A$46,B4,Matrix!$K$2:$K$46,3) -> 1 | F4: =SUM(C4:E4) -> 8 | G4: =IF(F4=0,0,E4/F4) -> 0.125 | H4: =IFERROR(AVERAGEIFS(Explanations!$H$2:$H$12,Explanations!$A$2:$A$12,A4,Explanations!$B$2:$B$12,B4),"n/a") -> 3
A5: DeepSeek | B5: Long Method | C5: =COUNTIFS(Matrix!$A$2:$A$46,B5,Matrix!$L$2:$L$46,1) -> 4 | D5: =COUNTIFS(Matrix!$A$2:$A$46,B5,Matrix!$L$2:$L$46,2) -> 7 | E5: =COUNTIFS(Matrix!$A$2:$A$46,B5,Matrix!$L$2:$L$46,3) -> 3 | F5: =SUM(C5:E5) -> 14 | G5: =IF(F5=0,0,E5/F5) -> 0.21428571 | H5: =IFERROR(AVERAGEIFS(Explanations!$H$2:$H$12,Explanations!$A$2:$A$12,A5,Explanations!$B$2:$B$12,B5),"n/a") -> 3
A6: DeepSeek | B6: God Class | C6: =COUNTIFS(Matrix!$A$2:$A$46,B6,Matrix!$L$2:$L$46,1) -> 3 | D6: =COUNTIFS(Matrix!$A$2:$A$46,B6,Matrix!$L$2:$L$46,2) -> 0 | E6: =COUNTIFS(Matrix!$A$2:$A$46,B6,Matrix!$L$2:$L$46,3) -> 5 | F6: =SUM(C6:E6) -> 8 | G6: =IF(F6=0,0,E6/F6) -> 0.625 | H6: =IFERROR(AVERAGEIFS(Explanations!$H$2:$H$12,Explanations!$A$2:$A$12,A6,Explanations!$B$2:$B$12,B6),"n/a") -> 3
A7: DeepSeek | B7: Long Parameter List | C7: =COUNTIFS(Matrix!$A$2:$A$46,B7,Matrix!$L$2:$L$46,1) -> 9 | D7: =COUNTIFS(Matrix!$A$2:$A$46,B7,Matrix!$L$2:$L$46,2) -> 1 | E7: =COUNTIFS(Matrix!$A$2:$A$46,B7,Matrix!$L$2:$L$46,3) -> 4 | F7: =SUM(C7:E7) -> 14 | G7: =IF(F7=0,0,E7/F7) -> 0.28571429 | H7: =IFERROR(AVERAGEIFS(Explanations!$H$2:$H$12,Explanations!$A$2:$A$12,A7,Explanations!$B$2:$B$12,B7),"n/a") -> 2

Sheet Explanations
A1: LLM | B1: Smell | C1: Detection # (Run 1, source order) | D1: Code unit | E1: Code reference (0/1) | F1: Smell characteristic (0/1) | G1: Evidence-to-smell link (0/1) | H1: Score (/3) | I1: Rationale
A2: ChatGPT | B2: Long Method | C2: 1 | D2: DefaultParser.handleShortAndLongOption(String) | E2: 1 | F2: 1 | G2: 1 | H2: =SUM(E2:G2) -> 3 | I2: Cites handleOption(), handleLongOptionWithoutEqual(), handleConcatenatedOptions(), currentOption.processValue(); says length plus many token-parsing cases make control flow hard to follow.
A3: ChatGPT | B3: Long Method | C3: 2 | D3: GnuParser.flatten(Options, String[], boolean) | E3: 1 | F3: 1 | G3: 1 | H3: =SUM(E3:G3) -> 3 | I3: Cites eatTheRest, indexOfEqual(), options.hasOption(); says it combines traversal, recognition and splitting, so is more complex than a single operation.
A4: ChatGPT | B4: God Class | C4: 1 | D4: HelpFormatter | E4: 1 | F4: 1 | G4: 1 | H4: =SUM(E4:G4) -> 3 | I4: Lists printHelp/printUsage/findWrapPos, fields defaultWidth/optionComparator; says formatting, layout, wrapping and output are combined in one large class.
A5: ChatGPT | B5: Long Parameter List | C5: 1 | D5: HelpFormatter.printHelp(int, String, String, Options, String, boolean) | E5: 1 | F5: 1 | G5: 1 | H5: =SUM(E5:G5) -> 3 | I5: Names all six parameters; says six separate inputs exceed a comfortable signature size.
A6: ChatGPT | B6: Long Parameter List | C6: 2 | D6: HelpFormatter.printHelp(PrintWriter, int, String, String, Options, int, int, String) | E6: 1 | F6: 1 | G6: 1 | H6: =SUM(E6:G6) -> 3 | I6: Names all eight parameters; says independent arguments make the signature cumbersome to call correctly.
A7: DeepSeek | B7: Long Method | C7: 1 | D7: DefaultParser.handleShortAndLongOption(String) | E7: 1 | F7: 1 | G7: 1 | H7: =SUM(E7:G7) -> 3 | I7: Quotes the actual conditions (token.length() == 1, pos == -1, isJavaProperty...); says many alternative token shapes make the flow long and hard to follow.
A8: DeepSeek | B8: Long Method | C8: 2 | D8: DefaultParser.parse(Options, Properties, NonOptionAction, String...) | E8: 1 | F8: 1 | G8: 1 | H8: =SUM(E8:G8) -> 3 | I8: Quotes expectedOpts, setSelected(null), handleToken, checkRequiredArgs; says setup, dispatch, reset, properties and validation are bundled in one body.
A9: DeepSeek | B9: God Class | C9: 1 | D9: CommandLine | E9: 1 | F9: 1 | G9: 1 | H9: =SUM(E9:G9) -> 3 | I9: Lists getParsedOptionValue overloads, resolveOption, handleDeprecated; says it covers storage, lookup, typed parsing, properties and iteration.
A10: DeepSeek | B10: God Class | C10: 2 | D10: DefaultParser | E10: 1 | F10: 1 | G10: 1 | H10: =SUM(E10:G10) -> 3 | I10: Lists fields (cmd, currentOption, skipParsing) and helpers; says it owns classification, matching, bookkeeping, properties and CommandLine construction.
A11: DeepSeek | B11: Long Parameter List | C11: 1 | D11: DefaultParser.parse(Options, Properties, NonOptionAction, String...) | E11: 1 | F11: 0 | G11: 0 | H11: =SUM(E11:G11) -> 1 | I11: Names the four parameters, but only says the signature "carries several unrelated concerns"; never says the list is long or hard to call, so no smell characteristic and no link.
A12: DeepSeek | B12: Long Parameter List | C12: 2 | D12: HelpFormatter.appendOptions(A, int, Options, int, int) | E12: 1 | F12: 1 | G12: 1 | H12: =SUM(E12:G12) -> 3 | I12: Names the five parameters; says they are passed positionally and make the call hard to interpret.

Sheet Rules & flags
A1: Matching rules used (state these in the report)
A2: 1. A detection = one smell reported for one code unit. Units: class for God Class; Class.method(parameter types) for Long Method and Long Parameter List.
A3: 2. Two detections are "the same" only if smell, FILE and code unit (including parameter types) are identical. Overloads such as HelpFormatter.printHelp(...) are different units.
A4: 3. Generic type "A" (A extends Appendable) is treated as Appendable; varargs String... is treated as String[]. cli/HelpFormatter and cli/help/HelpFormatter are different classes.
A5: 4. Every item an LLM listed is counted as a detection, including ones it called borderline or low-confidence.
A6: 5. PMD settings: GodClass default; NcssCount methodReportLevel=30; ExcessiveParameterList minimum=5; run on the comment-stripped sources (34 files).
A7: 6. DeepSeek run 2 listed two Builder setters as one entry; split into two units (code-unit level).
A8: 7. Distinct detections per LLM = union of units across its 3 runs; consistency = detections found in all 3 runs / distinct detections.
A9: Explanations sheet: scored draft (Claude); the student should review. ChatGPT God Class has one Run 1 detection, so one explanation; 11 explanations in total.
